Workbook

Sheet Summary
A1: Cash Flow for Prabh Solutions FY26-27 | F1: All Figures are in Rupees
C2: Total Cost | D2: April | E2: May | F2: June | G2: July | H2: Aug | I2: Sep | J2: Oct | K2: Nov | L2: Dec | M2: Jan | N2: Feb | O2: March
A3: CASH FLOW | D3: July | E3: August | F3: September | G3: October | H3: November | I3: December | J3: January | K3: February | L3: March | M3: April | N3: May | O3: June
A4: OPENING BALANCE | B4: Customer | D4: 0 | E4: =D30 -> 1552236 | F4: =E30 -> 3196021.9 | G4: =F30 -> 3298257.9 | H4: =G30 -> 5775293.9 | I4: =H30 -> 6204696.8 | J4: =I30 -> 6106932.8 | K4: =J30 -> 7568968.8 | L4: =K30 -> 7953371.7 | ... O4: =N30 -> 9832079.7
A5: Cash incoming | B5: Distributor
A6: Consulting Sales | C6: =Income!D5 -> 5635000 | D6: =Income!E5 -> 1650000 | E6: =Income!F5 -> 0 | F6: =Income!G5 -> 0 | G6: =Income!H5 -> 1700000 | H6: =Income!I5 -> 0 | I6: =Income!J5 -> 0 | J6: =Income!K5 -> 685000 | ... O6: =Income!P5 -> 850000
A7: Audit Sales | C7: =Income!D12 -> 600000 | D7: =Income!E12 -> 0 | E7: =Income!F12 -> 0 | F7: =Income!G12 -> 0 | G7: =Income!H12 -> 0 | H7: =Income!I12 -> 0 | I7: =Income!J12 -> 0 | J7: =Income!K12 -> 0 | ... O7: =Income!P12 -> 600000
A8: Implementation | C8: =Income!D17 -> 245000 | D8: =Income!E17 -> 0 | E8: =Income!F17 -> 0 | F8: =Income!G17 -> 200000 | G8: =Income!H17 -> 0 | H8: =Income!I17 -> 45000 | I8: =Income!J17 -> 0 | J8: =Income!K17 -> 0 | ... O8: =Income!P17 -> 0
A9: Management Charges | C9: =Income!D24 -> 6570723 | D9: =Income!E24 -> 45000 | E9: =Income!F24 -> 1552741 | F9: =Income!G24 -> 45000 | G9: =Income!H24 -> 1017000 | H9: =Income!I24 -> 580741 | I9: =Income!J24 -> 45000 | J9: =Income!K24 -> 1017000 | ... O9: =Income!P24 -> 45000
A10: Product Supply | C10: =Income!D31 -> 384583 | D10: =Income!E31 -> 0 | E10: =Income!F31 -> 384583 | F10: =Income!G31 -> 0 | G10: =Income!H31 -> 0 | H10: =Income!I31 -> 0 | I10: =Income!J31 -> 0 | J10: =Income!K31 -> 0 | ... O10: =Income!P31 -> 0
A12: Total incoming | C12: =SUM(C6:C11) -> 13435306 | D12: =SUM(D6:D11) -> 1695000 | E12: =SUM(E6:E11) -> 1937324 | F12: =SUM(F6:F11) -> 245000 | G12: =SUM(G6:G11) -> 2717000 | H12: =SUM(H6:H11) -> 625741 | I12: =SUM(I6:I11) -> 45000 | J12: =SUM(J6:J11) -> 1702000 | ... O12: =SUM(O6:O11) -> 1495000
A14: Cash outgoing
A15: Project Team | C15: =Expense!C7 -> 287500
A16: Onsite | C16: =Expense!C17 -> 129100
A17: Backoffice | C17: =Expense!C23 -> 89925
A19: SWATI MAHESH PF Payment | B19: Prabhsol | C19: =Expense!C28 -> 23264 | D19: 23264 | E19: 23264 | F19: 23264 | G19: 23264 | H19: 23264 | I19: 23264 | J19: 23264 | K19: 23264 | L19: 23264 | M19: 23264 | N19: 23264 | O19: 23264
A20: OD - INT | B20: Prabhsol | C20: =Expense!C32 -> 120000 | D20: 115000 | E20: 115000 | F20: 115000 | G20: 115000 | H20: 115000 | I20: 115000 | J20: 115000 | K20: 115000 | L20: 115000 | M20: 115000 | N20: 115000 | O20: 115000
A21: TDS Deduction | B21: Prabhsol | C21: =Expense!C29 -> 0 | D21: =(SUM(D9))*10% -> 4500 | E21: =(SUM(E9))*10% -> 155274.1 | F21: =(SUM(F9))*10% -> 4500 | G21: =(SUM(G9))*10% -> 101700 | H21: =(SUM(H9))*10% -> 58074.1 | I21: =(SUM(I9))*10% -> 4500 | J21: =SUM(J7:J9)*10% -> 101700 | K21: =SUM(K7:K9)*10% -> 58074.1 | L21: =SUM(L7:L9)*10% -> 4500 | M21: =SUM(M7:M9)*10% -> 106450 | N21: =SUM(N7:N9)*10% -> 60550 | O21: =SUM(O7:O9)*10% -> 64500
A23: Purchase
A27: Total outgoing | C27: =SUM(C15:C26) -> 649789 | D27: =SUM(D15:D23) -> 142764 | E27: =SUM(E15:E23) -> 293538.1 | F27: =SUM(F15:F23) -> 142764 | G27: =SUM(G15:G23) -> 239964 | H27: =SUM(H15:H23) -> 196338.1 | I27: =SUM(I15:I23) -> 142764 | J27: =SUM(J15:J23) -> 239964 | K27: =SUM(K15:K23) -> 196338.1 | ... O27: =SUM(O15:O23) -> 202764
A29: Monthly cash balance | C29: =C12-C27 -> 12785517 | D29: =D12-D27 -> 1552236 | E29: =E12-E27 -> 1643785.9 | F29: =F12-F27 -> 102236 | G29: =G12-G27 -> 2477036 | H29: =H12-H27 -> 429402.9 | I29: =I12-I27 -> -97764 | J29: =J12-J27 -> 1462036 | ... O29: =O12-O27 -> 1292236
A30: CLOSING BALANCE | D30: =(D4+D12)-D27 -> 1552236 | E30: =(E4+E12)-E27 -> 3196021.9 | F30: =(F4+F12)-F27 -> 3298257.9 | G30: =(G4+G12)-G27 -> 5775293.9 | H30: =(H4+H12)-H27 -> 6204696.8 | I30: =(I4+I12)-I27 -> 6106932.8 | J30: =(J4+J12)-J27 -> 7568968.8 | K30: =(K4+K12)-K27 -> 7953371.7 | ... O30: =(O4+O12)-O27 -> 11124316

Sheet Income
A1: Cash Flow for Prabh Solutions FY26-27 | G1: All Figures are in Rupees
C2: Total Quote | D2: Total Cost | E2: April | F2: May | G2: June | H2: July | I2: Aug | J2: Sep | K2: Oct | L2: Nov | M2: Dec | N2: Jan | O2: Feb | P2: March
A3: CASH FLOW | E3: July | F3: August | G3: September | H3: October | I3: November | J3: December | K3: January | L3: February | M3: March | N3: April | O3: May | P3: June
A4: Cash incoming | B4: Distributor
A5: Consulting Sales | D5: =SUM(D6:D10) -> 5635000 | E5: =SUM(E6:E10) -> 1650000 | F5: =SUM(F6:F10) -> 0 | G5: =SUM(G6:G10) -> 0 | H5: =SUM(H6:H10) -> 1700000 | I5: =SUM(I6:I10) -> 0 | J5: =SUM(J6:J10) -> 0 | K5: =SUM(K6:K10) -> 685000 | ... P5: =SUM(P6:P10) -> 850000
A6: Digital Edge BOM 2 | B6: Relight | C6: 450000 | D6: =SUM(E6:P6) -> 335000 | K6: 135000 | O6: 200000
A7: Lumina BOM 2 | B7: Relight | C7: 300000 | D7: =SUM(E7:P7) -> 300000 | P7: 300000
A8: Kotak Trust Residence | B8: Relight | C8: 100000 | D8: =SUM(E8:P8) -> 50000 | H8: 50000
A9: PDG Consulting | B9: Relight | C9: 5500000 | D9: =SUM(E9:P9) -> 4950000 | E9: 1650000 | H9: 1650000 | K9: 550000 | N9: 550000 | P9: 550000
D10: =SUM(E10:P10) -> 0
A12: Audit Sales | D12: =SUM(D13:D15) -> 600000 | E12: =SUM(E13:E15) -> 0 | F12: =SUM(F13:F15) -> 0 | G12: =SUM(G13:G15) -> 0 | H12: =SUM(H13:H15) -> 0 | I12: =SUM(I13:I15) -> 0 | J12: =SUM(J13:J15) -> 0 | K12: =SUM(K13:K15) -> 0 | ... P12: =SUM(P13:P15) -> 600000
A13: E&Y - First source | B13: E&Y | C13: 600000 | D13: =SUM(E13:P13) -> 600000 | P13: 600000
N14: =95000/2 -> 47500
D15: =SUM(E15:P15) -> 0
A17: Implementation | D17: =SUM(D18:D22) -> 245000 | E17: =SUM(E18:E22) -> 0 | F17: =SUM(F18:F22) -> 0 | G17: =SUM(G18:G22) -> 200000 | H17: =SUM(H18:H22) -> 0 | I17: =SUM(I18:I22) -> 45000 | J17: =SUM(J18:J22) -> 0 | K17: =SUM(K18:K22) -> 0 | ... P17: =SUM(P18:P22) -> 0
A18: Yatra Firewall | B18: Yatra | C18: 150000 | D18: =SUM(E18:P18) -> 150000 | G18: 150000
A19: RBL Finserve Videoconference | B19: RBL | C19: 45000 | D19: =SUM(E19:P19) -> 45000 | I19: 45000
A20: Star Health Tacacs | B20: Star health | C20: 50000 | D20: =SUM(E20:P20) -> 50000 | G20: 50000
O21: 25000
D22: =SUM(E22:P22) -> 0
A24: Management Charges | D24: =SUM(D25:D28) -> 6570723 | E24: =SUM(E25:E28) -> 45000 | F24: =SUM(F25:F28) -> 1552741 | G24: =SUM(G25:G28) -> 45000 | H24: =SUM(H25:H28) -> 1017000 | I24: =SUM(I25:I28) -> 580741 | J24: =SUM(J25:J28) -> 45000 | K24: =SUM(K25:K28) -> 1017000 | ... P24: =SUM(P25:P28) -> 45000
A25: Yatra | B25: Yatra | D25: =SUM(E25:P25) -> 1652723 | F25: 413241 | I25: 413241 | L25: 413241 | O25: 413000
A26: Excel | B26: Excel | D26: =SUM(E26:P26) -> 540000 | E26: 45000 | F26: 45000 | G26: 45000 | H26: 45000 | I26: 45000 | J26: 45000 | K26: 45000 | L26: 45000 | M26: 45000 | N26: 45000 | O26: 45000 | P26: 45000
A27: Nomura | B27: Nomura | D27: =SUM(E27:P27) -> 490000 | F27: 122500 | I27: 122500 | L27: 122500 | O27: 122500
A28: Start Health Insurance | B28: StarHI | D28: =SUM(E28:P28) -> 3888000 | F28: =108000*3*3 -> 972000 | H28: =108000*3*3 -> 972000 | K28: =108000*3*3 -> 972000 | N28: =108000*3*3 -> 972000
A31: Product Supply | D31: =SUM(D32:D40) -> 384583 | E31: =SUM(E32:E40) -> 0 | F31: =SUM(F32:F40) -> 384583 | G31: =SUM(G32:G40) -> 0 | H31: =SUM(H32:H40) -> 0 | I31: =SUM(I32:I40) -> 0 | J31: =SUM(J32:J40) -> 0 | K31: =SUM(K32:K40) -> 0 | ... P31: =SUM(P32:P40) -> 0
A32: Star Health TACACs | B32: Yatra | D32: =SUM(E32:P32) -> 384583 | F32: 384583
D34: =SUM(E34:P34) -> 0
D35: =SUM(E35:P35) -> 0
D36: =SUM(E36:P36) -> 0
D37: =SUM(E37:P37) -> 0
D38: =SUM(E38:P38) -> 0
D39: =SUM(E39:P39) -> 0
D40: =SUM(E40:P40) -> 0
A41: Product Services Supply | D41: =SUM(D42:D50) -> 0 | E41: =SUM(E42:E50) -> 0 | F41: =SUM(F42:F50) -> 0 | G41: =SUM(G42:G50) -> 0 | H41: =SUM(H42:H50) -> 0 | I41: =SUM(I42:I50) -> 0 | J41: =SUM(J42:J50) -> 0 | K41: =SUM(K42:K50) -> 0 | ... O41: =SUM(O42:O50) -> 0
D42: =SUM(E42:P42) -> 0
D43: =SUM(E43:P43) -> 0
D44: =SUM(E44:P44) -> 0
D45: =SUM(E45:P45) -> 0
D46: =SUM(E46:P46) -> 0
...

Sheet Expense
A1: Cash Flow for Prabh Solutions FY26-27 | F1: All Figures are in Rupees
C2: Total Cost | D2: April | E2: May | F2: June | G2: July | H2: Aug | I2: Sep | J2: Oct | K2: Nov | L2: Dec | M2: Jan | N2: Feb | O2: March
A3: CASH FLOW | D3: July | E3: August | F3: September | G3: October | H3: November | I3: December | J3: January | K3: February | L3: March | M3: April | N3: May | O3: June
B4: Distributor
A6: Cash outgoing
A7: Project Team | C7: =SUM(C8:C15) -> 287500 | D7: =SUM(D8:D15) -> 545850 | E7: =SUM(E8:E15) -> 0 | F7: =SUM(F8:F15) -> 0 | G7: =SUM(G8:G15) -> 0 | H7: =SUM(H8:H15) -> 0 | I7: =SUM(I8:I15) -> 0 | J7: =SUM(J8:J15) -> 0 | ... O7: =SUM(O8:O15) -> 0
A8: Emp 1 | B8: Prabhsol | C8: =SUM(D8:O8) -> 0
A9: Emp 2 | B9: Prabhsol | C9: =SUM(D9:O9) -> 0
A10: Emp 3 | B10: Prabhsol | C10: =SUM(D10:O10) -> 28000 | D10: 28000
A11: Emp 4 | B11: Prabhsol | C11: =SUM(D11:O11) -> 150000 | D11: 150000
A12: Emp 5 | B12: Prabhsol | C12: =SUM(D12:O12) -> 75000 | D12: 75000
A13: Emp 6 | B13: Prabhsol | D13: 58350
A14: Emp 7 | B14: Prabhsol | D14: 200000
A15: Emp 8 | B15: Prabhsol | C15: =SUM(D15:O15) -> 34500 | D15: 34500
A17: Onsite | C17: =SUM(C18:C21) -> 129100 | D17: =SUM(D18:D21) -> 129100 | E17: =SUM(E18:E21) -> 0 | F17: =SUM(F18:F21) -> 0 | G17: =SUM(G18:G21) -> 0 | H17: =SUM(H18:H21) -> 0 | I17: =SUM(I18:I21) -> 0 | J17: =SUM(J18:J21) -> 0 | ... O17: =SUM(O18:O21) -> 0
A18: Emp 9 | B18: Excel | C18: =SUM(D18:O18) -> 39200 | D18: 39200
A19: Emp 10 | B19: Yatra | C19: =SUM(D19:O19) -> 25000 | D19: 25000
A20: Emp 11 | B20: Yatra | C20: =SUM(D20:O20) -> 64900 | D20: 64900
A23: Backoffice | C23: =SUM(C24:C26) -> 89925 | D23: =SUM(D24:D26) -> 89925 | E23: =SUM(E24:E26) -> 0 | F23: =SUM(F24:F26) -> 0 | G23: =SUM(G24:G26) -> 0 | H23: =SUM(H24:H26) -> 0 | I23: =SUM(I24:I26) -> 0 | J23: =SUM(J24:J26) -> 0 | ... O23: =SUM(O24:O26) -> 0
A24: Emp 12 | B24: Prabhsol | C24: =SUM(D24:O24) -> 22525 | D24: 22525
A25: Emp 13 | B25: Prabhsol | C25: =SUM(D25:O25) -> 14400 | D25: 14400
A26: Office Rent | B26: Prabhsol | C26: =SUM(D26:O26) -> 53000 | D26: 53000
A28: SWATI MAHESH PF Payment | B28: Prabhsol | C28: =SUM(D28:O28) -> 23264 | D28: 23264
A29: TDS Deduction | B29: Prabhsol | C29: =SUM(D29:O29) -> 0
A31: Banks Intrest
A32: Bank Interest | B32: Prabhsol | C32: =SUM(D32:O32) -> 120000 | D32: 10000 | E32: 10000 | F32: 10000 | G32: 10000 | H32: 10000 | I32: 10000 | J32: 10000 | K32: 10000 | L32: 10000 | M32: 10000 | N32: 10000 | O32: 10000
A37: Purchase - Payments | C37: =SUM(C38:C54) -> 0 | D37: =SUM(D38:D54) -> 0 | E37: =SUM(E38:E54) -> 0 | F37: =SUM(F38:F54) -> 0 | G37: =SUM(G38:G54) -> 0 | H37: =SUM(H38:H54) -> 0 | I37: =SUM(I38:I54) -> 0 | J37: =SUM(J38:J54) -> 0 | ... O37: =SUM(O38:O54) -> 0
C38: =SUM(D38:O38) -> 0
C39: =SUM(D39:O39) -> 0
C40: =SUM(D40:O40) -> 0
C41: =SUM(D41:O41) -> 0
C42: =SUM(D42:O42) -> 0
C43: =SUM(D43:O43) -> 0
C44: =SUM(D44:O44) -> 0
C45: =SUM(D45:O45) -> 0
C46: =SUM(D46:O46) -> 0
C47: =SUM(D47:O47) -> 0
C48: =SUM(D48:O48) -> 0
C49: =SUM(D49:O49) -> 0
... C53: =SUM(D53:O53) -> 0
...
